Workbook

Sheet Riga_re
A1: op_type | B1: district | C1: street | D1: rooms | E1: area | F1: floor | G1: total_floors | H1: house_seria | I1: house_type | J1: condition | K1: price | L1: lat | M1: lon
A2: For rent | B2: Purvciems | C2: Dzelzavas 93 | D2: 1 | E2: 27 | F2: 3 | G2: 5 | H2: LT proj. | I2: Brick-Panel | J2: All amenities | K2: 250 | L2: 56.955484 | M2: 24.202139
A3: For rent | B3: Ziepniekkalns | C3: Ozolciema 32 | D3: 2 | E3: 50 | F3: 7 | G3: 9 | H3: 602 | I3: Panel | J3: All amenities | K3: 300 | L3: 56.899798 | M3: 24.09835
A4: For sale | B4: centrs | C4: Ieroču 6 | D4: 2 | E4: 33 | F4: 1 | G4: 2 | H4: P. kara | I4: Wood | J4: Partial amenities | K4: 13500 | L4: 56.975092 | M4: 24.139884
A5: For sale | B5: Ķengarags | C5: Maskavas 305 | D5: 2 | E5: 50 | F5: 5 | G5: 5 | H5: LT proj. | I5: Panel | J5: All amenities | K5: 34000 | L5: 56.859788 | M5: 24.308342
A6: For rent | B6: Teika | C6: Zemgala gatve 80 | D6: 3 | E6: 76 | F6: 3 | G6: 12 | H6: Jaun. | I6: Masonry | J6: All amenities | K6: 490 | L6: 56.977745 | M6: 24.166042
A7: For rent | B7: centrs | C7: Ģertrūdes 16 | D7: 2 | E7: 40 | F7: 3 | G7: 6 | H7: P. kara | I7: Masonry | J7: All amenities | K7: 440 | L7: 56.956659 | M7: 24.123764
A8: For sale | B8: Ķengarags | C8: Lokomotīves 20 | D8: 2 | E8: 37 | F8: 5 | G8: 5 | H8: Specpr. | I8: Brick | J8: All amenities | K8: 31000 | L8: 56.915273 | M8: 24.189365
A9: For rent | B9: Imanta | C9: Kurzemes pr. 46 | D9: 2 | E9: 49 | F9: 3 | G9: 5 | H9: LT proj. | I9: Panel | J9: All amenities | K9: 240 | L9: NaN | M9: NaN
A10: For rent | B10: centrs | C10: Avotu 7 | D10: 2 | E10: 48 | F10: 5 | G10: 5 | H10: P. kara | I10: Brick | J10: All amenities | K10: 400 | L10: 56.950944 | M10: 24.128358
A11: For rent | B11: Jugla | C11: Juglas 53 | D11: 2 | E11: 45 | F11: 2 | G11: 5 | H11: Hrušč. | I11: Panel | J11: All amenities | K11: 360 | L11: 56.976169 | M11: 24.25445
A12: For sale | B12: Mangaļi | C12: Mores 3 | D12: 2 | E12: 46 | F12: 4 | G12: 5 | H12: Hrušč. | I12: Panel | J12: All amenities | K12: 39999 | L12: 57.018811 | M12: 24.135012
A13: For sale | B13: Jugla | C13: Baltezera 1 | D13: 3 | E13: 58 | F13: 4 | G13: 5 | H13: Specpr. | I13: Brick | J13: All amenities | K13: 50000 | L13: 56.9927 | M13: 24.24006
A14: For sale | B14: Mežciems | C14: Gaiļezera 4 | D14: 2 | E14: 50 | F14: 1 | G14: 9 | H14: 602 | I14: Panel | J14: All amenities | K14: 53000 | L14: 56.967948 | M14: 24.235159
A15: For sale | B15: Maskavas priekšpilsēta | C15: Maskavas 291 k1 | D15: 3 | E15: 60 | F15: 2 | G15: 5 | H15: LT proj. | I15: Panel | J15: All amenities | K15: 48000 | L15: 56.922807 | M15: 24.170385
A16: For sale | B16: Zolitūde | C16: Zolitūdes 46/2 | D16: 1 | E16: 46 | F16: 9 | G16: 9 | H16: 119 | I16: Panel | J16: All amenities | K16: 38500 | L16: 56.946196 | M16: 24.001416
A17: For sale | B17: Mežciems | C17: Celmu 5 | D17: 2 | E17: 36 | F17: 1 | G17: 5 | H17: LT proj. | I17: Panel | J17: All amenities | K17: 46000 | L17: 56.973636 | M17: 24.233531
A18: For sale | B18: centrs | C18: Krāsotāju 25 | D18: 2 | E18: 36 | F18: 5 | G18: 5 | H18: P. kara | I18: Masonry | J18: All amenities | K18: 54900 | L18: 56.9563 | M18: 24.146759
A19: For rent | B19: Ziepniekkalns | C19: Ozolciema 54 | D19: 1 | E19: 44 | F19: 4 | G19: 9 | H19: M. ģim. | I19: Panel | J19: All amenities | K19: 240 | L19: 56.9014 | M19: 24.099886
A20: For sale | B20: Ķengarags | C20: Maskavas 268/5 | D20: 3 | E20: 60 | F20: 3 | G20: 5 | H20: Hrušč. | I20: Panel | J20: All amenities | K20: 56500 | L20: 56.894586 | M20: 24.216342
A21: For sale | B21: Mežciems | C21: Eizenšteina 57 | D21: 3 | E21: 62 | F21: 6 | G21: 9 | H21: 602 | I21: Panel | J21: All amenities | K21: 52500 | L21: 56.963423 | M21: 24.23513
A22: For rent | B22: Bolderāja | C22: Stagaru 4 | D22: 2 | E22: 50 | F22: 2 | G22: 5 | H22: Specpr. | I22: Panel | J22: All amenities | K22: 260 | L22: 57.029652 | M22: 24.035975
A23: For sale | B23: Purvciems | C23: Dzelzavas 13 | D23: 2 | E23: 44 | F23: 4 | G23: 5 | H23: Hrušč. | I23: Brick | J23: Without amenities | K23: 39000 | L23: 56.963679 | M23: 24.170617
A24: For rent | B24: centrs | C24: Čaka 33 | D24: 2 | E24: 40 | F24: 4 | G24: 6 | H24: P. kara | I24: Masonry | J24: All amenities | K24: 395 | L24: 56.952144 | M24: 24.127686
A25: For rent | B25: centrs | C25: Bruņinieku 115 | D25: 2 | E25: 45 | F25: 2 | G25: 4 | H25: Renov. | I25: Masonry | J25: All amenities | K25: 350 | L25: 56.949971 | M25: 24.144142
A26: For rent | B26: Grīziņkalns | C26: Alauksta 4a | D26: 1 | E26: 26 | F26: 2 | G26: 3 | H26: Renov. | I26: Wood | J26: All amenities | K26: 345 | L26: 56.96103 | M26: 24.147641
A27: For rent | B27: Ziepniekkalns | C27: Kartupeļu 47 | D27: 2 | E27: 56 | F27: 8 | G27: 9 | H27: Specpr. | I27: Brick | J27: All amenities | K27: 250 | L27: 56.91096 | M27: 24.11
A28: For rent | B28: Bolderāja | C28: Gobas 16 | D28: 1 | E28: 34 | F28: 3 | G28: 5 | H28: 103 | I28: Brick-Panel | J28: All amenities | K28: 210 | L28: 57.031352 | M28: 24.050865
A29: For sale | B29: Dreiliņi | C29: Valtera 5 | D29: 4 | E29: 78 | F29: 1 | G29: 9 | H29: 602 | I29: Panel | J29: All amenities | K29: 91000 | L29: 56.946927 | M29: 24.236511
A30: For sale | B30: Ķengarags | C30: Prūšu 22 | D30: 2 | E30: 42 | F30: 3 | G30: 5 | H30: Hrušč. | I30: Brick | J30: All amenities | K30: 45900 | L30: 56.913476 | M30: 24.186771
A31: For sale | B31: Pļavnieki | C31: Dzeņu 12 | D31: 1 | E31: 35 | F31: 1 | G31: 9 | H31: 602 | I31: Brick-Panel | J31: All amenities | K31: 37000 | L31: 56.939723 | M31: 24.212624
A32: For rent | B32: Dzegužkalns | C32: Purva 25 | D32: 1 | E32: 29 | F32: 4 | G32: 5 | H32: LT proj. | I32: Panel | J32: All amenities | K32: 240 | L32: 56.957703 | M32: 24.050521
A33: For rent | B33: Imanta | C33: Slokas 130a | D33: 2 | E33: 60 | F33: 3 | G33: 8 | H33: Jaun. | I33: Masonry | J33: All amenities | K33: 580 | L33: 56.964854 | M33: 24.015749
A34: For sale | B34: Imanta | C34: Slokas 130a | D34: 2 | E34: 62 | F34: 3 | G34: 5 | H34: Jaun. | I34: Masonry | J34: All amenities | K34: 120000 | L34: 56.964854 | M34: 24.015749
A35: For rent | B35: centrs | C35: Indrānu 13 | D35: 1 | E35: 34 | F35: 5 | G35: 5 | H35: LT proj. | I35: Brick-Panel | J35: All amenities | K35: 320 | L35: 56.968596 | M35: 24.145257
A36: For sale | B36: Ķengarags | C36: Festivāla 1 | D36: 3 | E36: 55 | F36: 3 | G36: 5 | H36: Specpr. | I36: Brick | J36: All amenities | K36: 43000 | L36: 56.903488 | M36: 24.203698
A37: For rent | B37: Purvciems | C37: Ieriķu 58 | D37: 1 | E37: 43 | F37: 9 | G37: 9 | H37: Specpr. | I37: Brick | J37: All amenities | K37: 25 | L37: 56.965567 | M37: 24.183004
A38: For rent | B38: Ķīpsala | C38: Balasta d. 72 | D38: 2 | E38: 86 | F38: 2 | G38: 4 | H38: Jaun. | I38: Masonry | J38: All amenities | K38: 1200 | L38: 56.948934 | M38: 24.08828
A39: For rent | B39: centrs | C39: Barona 14 | D39: 1 | E39: 40 | F39: 4 | G39: 5 | H39: Renov. | I39: Masonry | J39: All amenities | K39: 600 | L39: 56.950615 | M39: 24.121231
A40: For rent | B40: centrs | C40: Bruņinieku 64 | D40: 2 | E40: 36 | F40: 3 | G40: 3 | H40: P. kara | I40: Brick | J40: All amenities | K40: 250 | L40: 56.953071 | M40: 24.137642
...

Sheet Analysis
A1: Metric | B1: Value
A2: Total rows | B2: =COUNTA(Riga_re!A:A)-1 -> 4689
A3: For sale | B3: =COUNTIF(Riga_re!A:A,"For sale") -> 2680
A4: For rent | B4: =COUNTIF(Riga_re!A:A,"For rent") -> 1525
A5: Avg price (sale) | B5: =AVERAGEIF(Riga_re!A:A,"For sale",Riga_re!K:K) -> 92103.718
A6: Avg price (rent) | B6: =AVERAGEIF(Riga_re!A:A,"For rent",Riga_re!K:K) -> 425.26885
A7: Blanks | B7: =COUNTBLANK(Riga_re!A2:A4690) -> 0
A8: Buying | B8: =COUNTIF(Riga_re!A:A,"Buying") -> 381
A9: Change | B9: =COUNTIF(Riga_re!A:A,"Change") -> 14
A10: Other | B10: =COUNTIF(Riga_re!A:A,"Other") -> 5
A11: Renting | B11: =COUNTIF(Riga_re!A:A,"Renting") -> 84
A12: Total excluded | B12: =SUM(B7:B11) -> 484
A14: Avg price 2-room centrs | B14: =AVERAGEIFS(Clean_data!K:K, Clean_data!B:B, "centrs", Clean_data!D:D, 2, Clean_data!A:A, "For sale") -> 91035.09
B16: =VLOOKUP("Dzelzavas 93", Clean_data!C:K, 9, 0) -> 250

Sheet Clean_data
A1: op_type | B1: district | C1: street | D1: rooms | E1: area | F1: floor | G1: total_floors | H1: house_seria | I1: house_type | J1: condition | K1: price | L1: lat | M1: lon
A2: =IFERROR(__xludf.DUMMYFUNCTION("FILTER(Riga_re!A1:M4690,(Riga_re!A1:A4690=""For sale"")+(Riga_re!A1:A4690=""For rent""))"),"For rent") -> For rent | B2: =IFERROR(__xludf.DUMMYFUNCTION("""COMPUTED_VALUE"""),"Purvciems") -> Purvciems | C2: =IFERROR(__xludf.DUMMYFUNCTION("""COMPUTED_VALUE"""),"Dzelzavas 93") -> Dzelzavas 93 | D2: =IFERROR(__xludf.DUMMYFUNCTION("""COMPUTED_VALUE"""),1.0) -> 1 | E2: =IFERROR(__xludf.DUMMYFUNCTION("""COMPUTED_VALUE"""),27.0) -> 27 | F2: =IFERROR(__xludf.DUMMYFUNCTION("""COMPUTED_VALUE"""),3.0) -> 3 | G2: =IFERROR(__xludf.DUMMYFUNCTION("""COMPUTED_VALUE"""),5.0) -> 5 | H2: =IFERROR(__xludf.DUMMYFUNCTION("""COMPUTED_VALUE"""),"LT proj.") -> LT proj. | I2: =IFERROR(__xludf.DUMMYFUNCTION("""COMPUTED_VALUE"""),"Brick-Panel") -> Brick-Panel | J2: =IFERROR(__xludf.DUMMYFUNCTION("""COMPUTED_VALUE"""),"All amenities") -> All amenities | K2: =IFERROR(__xludf.DUMMYFUNCTION("""COMPUTED_VALUE"""),250.0) -> 250 | L2: =IFERROR(__xludf.DUMMYFUNCTION("""COMPUTED_VALUE"""),56.9554841) -> 56.955484 | M2: =IFERROR(__xludf.DUMMYFUNCTION("""COMPUTED_VALUE"""),24.2021393392559) -> 24.202139 | O2: =COUNTA(A:A) -> 4206
A3: =IFERROR(__xludf.DUMMYFUNCTION("""COMPUTED_VALUE"""),"For rent") -> For rent | B3: =IFERROR(__xludf.DUMMYFUNCTION("""COMPUTED_VALUE"""),"Ziepniekkalns") -> Ziepniekkalns | C3: =IFERROR(__xludf.DUMMYFUNCTION("""COMPUTED_VALUE"""),"Ozolciema 32") -> Ozolciema 32 | D3: =IFERROR(__xludf.DUMMYFUNCTION("""COMPUTED_VALUE"""),2.0) -> 2 | E3: =IFERROR(__xludf.DUMMYFUNCTION("""COMPUTED_VALUE"""),50.0) -> 50 | F3: =IFERROR(__xludf.DUMMYFUNCTION("""COMPUTED_VALUE"""),7.0) -> 7 | G3: =IFERROR(__xludf.DUMMYFUNCTION("""COMPUTED_VALUE"""),9.0) -> 9 | H3: =IFERROR(__xludf.DUMMYFUNCTION("""COMPUTED_VALUE"""),602.0) -> 602 | I3: =IFERROR(__xludf.DUMMYFUNCTION("""COMPUTED_VALUE"""),"Panel") -> Panel | J3: =IFERROR(__xludf.DUMMYFUNCTION("""COMPUTED_VALUE"""),"All amenities") -> All amenities | K3: =IFERROR(__xludf.DUMMYFUNCTION("""COMPUTED_VALUE"""),300.0) -> 300 | L3: =IFERROR(__xludf.DUMMYFUNCTION("""COMPUTED_VALUE"""),56.89979805) -> 56.899798 | M3: =IFERROR(__xludf.DUMMYFUNCTION("""COMPUTED_VALUE"""),24.09835015) -> 24.09835
A4: =IFERROR(__xludf.DUMMYFUNCTION("""COMPUTED_VALUE"""),"For sale") -> For sale | B4: =IFERROR(__xludf.DUMMYFUNCTION("""COMPUTED_VALUE"""),"centrs") -> centrs | C4: =IFERROR(__xludf.DUMMYFUNCTION("""COMPUTED_VALUE"""),"Ieroču 6") -> Ieroču 6 | D4: =IFERROR(__xludf.DUMMYFUNCTION("""COMPUTED_VALUE"""),2.0) -> 2 | E4: =IFERROR(__xludf.DUMMYFUNCTION("""COMPUTED_VALUE"""),33.0) -> 33 | F4: =IFERROR(__xludf.DUMMYFUNCTION("""COMPUTED_VALUE"""),1.0) -> 1 | G4: =IFERROR(__xludf.DUMMYFUNCTION("""COMPUTED_VALUE"""),2.0) -> 2 | H4: =IFERROR(__xludf.DUMMYFUNCTION("""COMPUTED_VALUE"""),"P. kara") -> P. kara | I4: =IFERROR(__xludf.DUMMYFUNCTION("""COMPUTED_VALUE"""),"Wood") -> Wood | J4: =IFERROR(__xludf.DUMMYFUNCTION("""COMPUTED_VALUE"""),"Partial amenities") -> Partial amenities | K4: =IFERROR(__xludf.DUMMYFUNCTION("""COMPUTED_VALUE"""),13500.0) -> 13500 | L4: =IFERROR(__xludf.DUMMYFUNCTION("""COMPUTED_VALUE"""),56.9750922) -> 56.975092 | M4: =IFERROR(__xludf.DUMMYFUNCTION("""COMPUTED_VALUE"""),24.1398842) -> 24.139884
A5: =IFERROR(__xludf.DUMMYFUNCTION("""COMPUTED_VALUE"""),"For sale") -> For sale | B5: =IFERROR(__xludf.DUMMYFUNCTION("""COMPUTED_VALUE"""),"Ķengarags") -> Ķengarags | C5: =IFERROR(__xludf.DUMMYFUNCTION("""COMPUTED_VALUE"""),"Maskavas 305") -> Maskavas 305 | D5: =IFERROR(__xludf.DUMMYFUNCTION("""COMPUTED_VALUE"""),2.0) -> 2 | E5: =IFERROR(__xludf.DUMMYFUNCTION("""COMPUTED_VALUE"""),50.0) -> 50 | F5: =IFERROR(__xludf.DUMMYFUNCTION("""COMPUTED_VALUE"""),5.0) -> 5 | G5: =IFERROR(__xludf.DUMMYFUNCTION("""COMPUTED_VALUE"""),5.0) -> 5 | H5: =IFERROR(__xludf.DUMMYFUNCTION("""COMPUTED_VALUE"""),"LT proj.") -> LT proj. | I5: =IFERROR(__xludf.DUMMYFUNCTION("""COMPUTED_VALUE"""),"Panel") -> Panel | J5: =IFERROR(__xludf.DUMMYFUNCTION("""COMPUTED_VALUE"""),"All amenities") -> All amenities | K5: =IFERROR(__xludf.DUMMYFUNCTION("""COMPUTED_VALUE"""),34000.0) -> 34000 | L5: =IFERROR(__xludf.DUMMYFUNCTION("""COMPUTED_VALUE"""),56.8597884) -> 56.859788 | M5: =IFERROR(__xludf.DUMMYFUNCTION("""COMPUTED_VALUE"""),24.3083417) -> 24.308342
A6: =IFERROR(__xludf.DUMMYFUNCTION("""COMPUTED_VALUE"""),"For rent") -> For rent | B6: =IFERROR(__xludf.DUMMYFUNCTION("""COMPUTED_VALUE"""),"Teika") -> Teika | C6: =IFERROR(__xludf.DUMMYFUNCTION("""COMPUTED_VALUE"""),"Zemgala gatve 80") -> Zemgala gatve 80 | D6: =IFERROR(__xludf.DUMMYFUNCTION("""COMPUTED_VALUE"""),3.0) -> 3 | E6: =IFERROR(__xludf.DUMMYFUNCTION("""COMPUTED_VALUE"""),76.0) -> 76 | F6: =IFERROR(__xludf.DUMMYFUNCTION("""COMPUTED_VALUE"""),3.0) -> 3 | G6: =IFERROR(__xludf.DUMMYFUNCTION("""COMPUTED_VALUE"""),12.0) -> 12 | H6: =IFERROR(__xludf.DUMMYFUNCTION("""COMPUTED_VALUE"""),"Jaun.") -> Jaun. | I6: =IFERROR(__xludf.DUMMYFUNCTION("""COMPUTED_VALUE"""),"Masonry") -> Masonry | J6: =IFERROR(__xludf.DUMMYFUNCTION("""COMPUTED_VALUE"""),"All amenities") -> All amenities | K6: =IFERROR(__xludf.DUMMYFUNCTION("""COMPUTED_VALUE"""),490.0) -> 490 | L6: =IFERROR(__xludf.DUMMYFUNCTION("""COMPUTED_VALUE"""),56.9777452) -> 56.977745 | M6: =IFERROR(__xludf.DUMMYFUNCTION("""COMPUTED_VALUE"""),24.1660424135714) -> 24.166042
A7: =IFERROR(__xludf.DUMMYFUNCTION("""COMPUTED_VALUE"""),"For rent") -> For rent | B7: =IFERROR(__xludf.DUMMYFUNCTION("""COMPUTED_VALUE"""),"centrs") -> centrs | C7: =IFERROR(__xludf.DUMMYFUNCTION("""COMPUTED_VALUE"""),"Ģertrūdes 16") -> Ģertrūdes 16 | D7: =IFERROR(__xludf.DUMMYFUNCTION("""COMPUTED_VALUE"""),2.0) -> 2 | E7: =IFERROR(__xludf.DUMMYFUNCTION("""COMPUTED_VALUE"""),40.0) -> 40 | F7: =IFERROR(__xludf.DUMMYFUNCTION("""COMPUTED_VALUE"""),3.0) -> 3 | G7: =IFERROR(__xludf.DUMMYFUNCTION("""COMPUTED_VALUE"""),6.0) -> 6 | H7: =IFERROR(__xludf.DUMMYFUNCTION("""COMPUTED_VALUE"""),"P. kara") -> P. kara | I7: =IFERROR(__xludf.DUMMYFUNCTION("""COMPUTED_VALUE"""),"Masonry") -> Masonry | J7: =IFERROR(__xludf.DUMMYFUNCTION("""COMPUTED_VALUE"""),"All amenities") -> All amenities | K7: =IFERROR(__xludf.DUMMYFUNCTION("""COMPUTED_VALUE"""),440.0) -> 440 | L7: =IFERROR(__xludf.DUMMYFUNCTION("""COMPUTED_VALUE"""),56.9566594) -> 56.956659 | M7: =IFERROR(__xludf.DUMMYFUNCTION("""COMPUTED_VALUE"""),24.1237638) -> 24.123764
A8: =IFERROR(__xludf.DUMMYFUNCTION("""COMPUTED_VALUE"""),"For sale") -> For sale | B8: =IFERROR(__xludf.DUMMYFUNCTION("""COMPUTED_VALUE"""),"Ķengarags") -> Ķengarags | C8: =IFERROR(__xludf.DUMMYFUNCTION("""COMPUTED_VALUE"""),"Lokomotīves 20") -> Lokomotīves 20 | D8: =IFERROR(__xludf.DUMMYFUNCTION("""COMPUTED_VALUE"""),2.0) -> 2 | E8: =IFERROR(__xludf.DUMMYFUNCTION("""COMPUTED_VALUE"""),37.0) -> 37 | F8: =IFERROR(__xludf.DUMMYFUNCTION("""COMPUTED_VALUE"""),5.0) -> 5 | G8: =IFERROR(__xludf.DUMMYFUNCTION("""COMPUTED_VALUE"""),5.0) -> 5 | H8: =IFERROR(__xludf.DUMMYFUNCTION("""COMPUTED_VALUE"""),"Specpr.") -> Specpr. | I8: =IFERROR(__xludf.DUMMYFUNCTION("""COMPUTED_VALUE"""),"Brick") -> Brick | J8: =IFERROR(__xludf.DUMMYFUNCTION("""COMPUTED_VALUE"""),"All amenities") -> All amenities | K8: =IFERROR(__xludf.DUMMYFUNCTION("""COMPUTED_VALUE"""),31000.0) -> 31000 | L8: =IFERROR(__xludf.DUMMYFUNCTION("""COMPUTED_VALUE"""),56.91527335) -> 56.915273 | M8: =IFERROR(__xludf.DUMMYFUNCTION("""COMPUTED_VALUE"""),24.18936465) -> 24.189365
A9: =IFERROR(__xludf.DUMMYFUNCTION("""COMPUTED_VALUE"""),"For rent") -> For rent | B9: =IFERROR(__xludf.DUMMYFUNCTION("""COMPUTED_VALUE"""),"Imanta") -> Imanta | C9: =IFERROR(__xludf.DUMMYFUNCTION("""COMPUTED_VALUE"""),"Kurzemes pr. 46") -> Kurzemes pr. 46 | D9: =IFERROR(__xludf.DUMMYFUNCTION("""COMPUTED_VALUE"""),2.0) -> 2 | E9: =IFERROR(__xludf.DUMMYFUNCTION("""COMPUTED_VALUE"""),49.0) -> 49 | F9: =IFERROR(__xludf.DUMMYFUNCTION("""COMPUTED_VALUE"""),3.0) -> 3 | G9: =IFERROR(__xludf.DUMMYFUNCTION("""COMPUTED_VALUE"""),5.0) -> 5 | H9: =IFERROR(__xludf.DUMMYFUNCTION("""COMPUTED_VALUE"""),"LT proj.") -> LT proj. | I9: =IFERROR(__xludf.DUMMYFUNCTION("""COMPUTED_VALUE"""),"Panel") -> Panel | J9: =IFERROR(__xludf.DUMMYFUNCTION("""COMPUTED_VALUE"""),"All amenities") -> All amenities | K9: =IFERROR(__xludf.DUMMYFUNCTION("""COMPUTED_VALUE"""),240.0) -> 240 | L9: =IFERROR(__xludf.DUMMYFUNCTION("""COMPUTED_VALUE"""),"NaN") -> NaN | M9: =IFERROR(__xludf.DUMMYFUNCTION("""COMPUTED_VALUE"""),"NaN") -> NaN
A10: =IFERROR(__xludf.DUMMYFUNCTION("""COMPUTED_VALUE"""),"For rent") -> For rent | B10: =IFERROR(__xludf.DUMMYFUNCTION("""COMPUTED_VALUE"""),"centrs") -> centrs | C10: =IFERROR(__xludf.DUMMYFUNCTION("""COMPUTED_VALUE"""),"Avotu 7") -> Avotu 7 | D10: =IFERROR(__xludf.DUMMYFUNCTION("""COMPUTED_VALUE"""),2.0) -> 2 | E10: =IFERROR(__xludf.DUMMYFUNCTION("""COMPUTED_VALUE"""),48.0) -> 48 | F10: =IFERROR(__xludf.DUMMYFUNCTION("""COMPUTED_VALUE"""),5.0) -> 5 | G10: =IFERROR(__xludf.DUMMYFUNCTION("""COMPUTED_VALUE"""),5.0) -> 5 | H10: =IFERROR(__xludf.DUMMYFUNCTION("""COMPUTED_VALUE"""),"P. kara") -> P. kara | I10: =IFERROR(__xludf.DUMMYFUNCTION("""COMPUTED_VALUE"""),"Brick") -> Brick | J10: =IFERROR(__xludf.DUMMYFUNCTION("""COMPUTED_VALUE"""),"All amenities") -> All amenities | K10: =IFERROR(__xludf.DUMMYFUNCTION("""COMPUTED_VALUE"""),400.0) -> 400 | L10: =IFERROR(__xludf.DUMMYFUNCTION("""COMPUTED_VALUE"""),56.9509444) -> 56.950944 | M10: =IFERROR(__xludf.DUMMYFUNCTION("""COMPUTED_VALUE"""),24.128357771229) -> 24.128358
A11: =IFERROR(__xludf.DUMMYFUNCTION("""COMPUTED_VALUE"""),"For rent") -> For rent | B11: =IFERROR(__xludf.DUMMYFUNCTION("""COMPUTED_VALUE"""),"Jugla") -> Jugla | C11: =IFERROR(__xludf.DUMMYFUNCTION("""COMPUTED_VALUE"""),"Juglas 53") -> Juglas 53 | D11: =IFERROR(__xludf.DUMMYFUNCTION("""COMPUTED_VALUE"""),2.0) -> 2 | E11: =IFERROR(__xludf.DUMMYFUNCTION("""COMPUTED_VALUE"""),45.0) -> 45 | F11: =IFERROR(__xludf.DUMMYFUNCTION("""COMPUTED_VALUE"""),2.0) -> 2 | G11: =IFERROR(__xludf.DUMMYFUNCTION("""COMPUTED_VALUE"""),5.0) -> 5 | H11: =IFERROR(__xludf.DUMMYFUNCTION("""COMPUTED_VALUE"""),"Hrušč.") -> Hrušč. | I11: =IFERROR(__xludf.DUMMYFUNCTION("""COMPUTED_VALUE"""),"Panel") -> Panel | J11: =IFERROR(__xludf.DUMMYFUNCTION("""COMPUTED_VALUE"""),"All amenities") -> All amenities | K11: =IFERROR(__xludf.DUMMYFUNCTION("""COMPUTED_VALUE"""),360.0) -> 360 | L11: =IFERROR(__xludf.DUMMYFUNCTION("""COMPUTED_VALUE"""),56.9761694) -> 56.976169 | M11: =IFERROR(__xludf.DUMMYFUNCTION("""COMPUTED_VALUE"""),24.2544503) -> 24.25445
A12: =IFERROR(__xludf.DUMMYFUNCTION("""COMPUTED_VALUE"""),"For sale") -> For sale | B12: =IFERROR(__xludf.DUMMYFUNCTION("""COMPUTED_VALUE"""),"Mangaļi") -> Mangaļi | C12: =IFERROR(__xludf.DUMMYFUNCTION("""COMPUTED_VALUE"""),"Mores 3") -> Mores 3 | D12: =IFERROR(__xludf.DUMMYFUNCTION("""COMPUTED_VALUE"""),2.0) -> 2 | E12: =IFERROR(__xludf.DUMMYFUNCTION("""COMPUTED_VALUE"""),46.0) -> 46 | F12: =IFERROR(__xludf.DUMMYFUNCTION("""COMPUTED_VALUE"""),4.0) -> 4 | G12: =IFERROR(__xludf.DUMMYFUNCTION("""COMPUTED_VALUE"""),5.0) -> 5 | H12: =IFERROR(__xludf.DUMMYFUNCTION("""COMPUTED_VALUE"""),"Hrušč.") -> Hrušč. | I12: =IFERROR(__xludf.DUMMYFUNCTION("""COMPUTED_VALUE"""),"Panel") -> Panel | J12: =IFERROR(__xludf.DUMMYFUNCTION("""COMPUTED_VALUE"""),"All amenities") -> All amenities | K12: =IFERROR(__xludf.DUMMYFUNCTION("""COMPUTED_VALUE"""),39999.0) -> 39999 | L12: =IFERROR(__xludf.DUMMYFUNCTION("""COMPUTED_VALUE"""),57.0188111) -> 57.018811 | M12: =IFERROR(__xludf.DUMMYFUNCTION("""COMPUTED_VALUE"""),24.13501185) -> 24.135012
A13: =IFERROR(__xludf.DUMMYFUNCTION("""COMPUTED_VALUE"""),"For sale") -> For sale | B13: =IFERROR(__xludf.DUMMYFUNCTION("""COMPUTED_VALUE"""),"Jugla") -> Jugla | C13: =IFERROR(__xludf.DUMMYFUNCTION("""COMPUTED_VALUE"""),"Baltezera 1") -> Baltezera 1 | D13: =IFERROR(__xludf.DUMMYFUNCTION("""COMPUTED_VALUE"""),3.0) -> 3 | E13: =IFERROR(__xludf.DUMMYFUNCTION("""COMPUTED_VALUE"""),58.0) -> 58 | F13: =IFERROR(__xludf.DUMMYFUNCTION("""COMPUTED_VALUE"""),4.0) -> 4 | G13: =IFERROR(__xludf.DUMMYFUNCTION("""COMPUTED_VALUE"""),5.0) -> 5 | H13: =IFERROR(__xludf.DUMMYFUNCTION("""COMPUTED_VALUE"""),"Specpr.") -> Specpr. | I13: =IFERROR(__xludf.DUMMYFUNCTION("""COMPUTED_VALUE"""),"Brick") -> Brick | J13: =IFERROR(__xludf.DUMMYFUNCTION("""COMPUTED_VALUE"""),"All amenities") -> All amenities | K13: =IFERROR(__xludf.DUMMYFUNCTION("""COMPUTED_VALUE"""),50000.0) -> 50000 | L13: =IFERROR(__xludf.DUMMYFUNCTION("""COMPUTED_VALUE"""),56.9927002999999) -> 56.9927 | M13: =IFERROR(__xludf.DUMMYFUNCTION("""COMPUTED_VALUE"""),24.2400597) -> 24.24006
A14: =IFERROR(__xludf.DUMMYFUNCTION("""COMPUTED_VALUE"""),"For sale") -> For sale | B14: =IFERROR(__xludf.DUMMYFUNCTION("""COMPUTED_VALUE"""),"Mežciems") -> Mežciems | C14: =IFERROR(__xludf.DUMMYFUNCTION("""COMPUTED_VALUE"""),"Gaiļezera 4") -> Gaiļezera 4 | D14: =IFERROR(__xludf.DUMMYFUNCTION("""COMPUTED_VALUE"""),2.0) -> 2 | E14: =IFERROR(__xludf.DUMMYFUNCTION("""COMPUTED_VALUE"""),50.0) -> 50 | F14: =IFERROR(__xludf.DUMMYFUNCTION("""COMPUTED_VALUE"""),1.0) -> 1 | G14: =IFERROR(__xludf.DUMMYFUNCTION("""COMPUTED_VALUE"""),9.0) -> 9 | H14: =IFERROR(__xludf.DUMMYFUNCTION("""COMPUTED_VALUE"""),602.0) -> 602 | I14: =IFERROR(__xludf.DUMMYFUNCTION("""COMPUTED_VALUE"""),"Panel") -> Panel | J14: =IFERROR(__xludf.DUMMYFUNCTION("""COMPUTED_VALUE"""),"All amenities") -> All amenities | K14: =IFERROR(__xludf.DUMMYFUNCTION("""COMPUTED_VALUE"""),53000.0) -> 53000 | L14: =IFERROR(__xludf.DUMMYFUNCTION("""COMPUTED_VALUE"""),56.967948) -> 56.967948 | M14: =IFERROR(__xludf.DUMMYFUNCTION("""COMPUTED_VALUE"""),24.2351586311777) -> 24.235159
A15: =IFERROR(__xludf.DUMMYFUNCTION("""COMPUTED_VALUE"""),"For sale") -> For sale | B15: =IFERROR(__xludf.DUMMYFUNCTION("""COMPUTED_VALUE"""),"Maskavas priekšpilsēta") -> Maskavas priekšpilsēta | C15: =IFERROR(__xludf.DUMMYFUNCTION("""COMPUTED_VALUE"""),"Maskavas 291 k1") -> Maskavas 291 k1 | D15: =IFERROR(__xludf.DUMMYFUNCTION("""COMPUTED_VALUE"""),3.0) -> 3 | E15: =IFERROR(__xludf.DUMMYFUNCTION("""COMPUTED_VALUE"""),60.0) -> 60 | F15: =IFERROR(__xludf.DUMMYFUNCTION("""COMPUTED_VALUE"""),2.0) -> 2 | G15: =IFERROR(__xludf.DUMMYFUNCTION("""COMPUTED_VALUE"""),5.0) -> 5 | H15: =IFERROR(__xludf.DUMMYFUNCTION("""COMPUTED_VALUE"""),"LT proj.") -> LT proj. | I15: =IFERROR(__xludf.DUMMYFUNCTION("""COMPUTED_VALUE"""),"Panel") -> Panel | J15: =IFERROR(__xludf.DUMMYFUNCTION("""COMPUTED_VALUE"""),"All amenities") -> All amenities | K15: =IFERROR(__xludf.DUMMYFUNCTION("""COMPUTED_VALUE"""),48000.0) -> 48000 | L15: =IFERROR(__xludf.DUMMYFUNCTION("""COMPUTED_VALUE"""),56.9228069) -> 56.922807 | M15: =IFERROR(__xludf.DUMMYFUNCTION("""COMPUTED_VALUE"""),24.1703845) -> 24.170385
A16: =IFERROR(__xludf.DUMMYFUNCTION("""COMPUTED_VALUE"""),"For sale") -> For sale | B16: =IFERROR(__xludf.DUMMYFUNCTION("""COMPUTED_VALUE"""),"Zolitūde") -> Zolitūde | C16: =IFERROR(__xludf.DUMMYFUNCTION("""COMPUTED_VALUE"""),"Zolitūdes 46/2") -> Zolitūdes 46/2 | D16: =IFERROR(__xludf.DUMMYFUNCTION("""COMPUTED_VALUE"""),1.0) -> 1 | E16: =IFERROR(__xludf.DUMMYFUNCTION("""COMPUTED_VALUE"""),46.0) -> 46 | F16: =IFERROR(__xludf.DUMMYFUNCTION("""COMPUTED_VALUE"""),9.0) -> 9 | G16: =IFERROR(__xludf.DUMMYFUNCTION("""COMPUTED_VALUE"""),9.0) -> 9 | H16: =IFERROR(__xludf.DUMMYFUNCTION("""COMPUTED_VALUE"""),119.0) -> 119 | I16: =IFERROR(__xludf.DUMMYFUNCTION("""COMPUTED_VALUE"""),"Panel") -> Panel | J16: =IFERROR(__xludf.DUMMYFUNCTION("""COMPUTED_VALUE"""),"All amenities") -> All amenities | K16: =IFERROR(__xludf.DUMMYFUNCTION("""COMPUTED_VALUE"""),38500.0) -> 38500 | L16: =IFERROR(__xludf.DUMMYFUNCTION("""COMPUTED_VALUE"""),56.9461963) -> 56.946196 | M16: =IFERROR(__xludf.DUMMYFUNCTION("""COMPUTED_VALUE"""),24.0014164) -> 24.001416
A17: =IFERROR(__xludf.DUMMYFUNCTION("""COMPUTED_VALUE"""),"For sale") -> For sale | B17: =IFERROR(__xludf.DUMMYFUNCTION("""COMPUTED_VALUE"""),"Mežciems") -> Mežciems | C17: =IFERROR(__xludf.DUMMYFUNCTION("""COMPUTED_VALUE"""),"Celmu 5") -> Celmu 5 | D17: =IFERROR(__xludf.DUMMYFUNCTION("""COMPUTED_VALUE"""),2.0) -> 2 | E17: =IFERROR(__xludf.DUMMYFUNCTION("""COMPUTED_VALUE"""),36.0) -> 36 | F17: =IFERROR(__xludf.DUMMYFUNCTION("""COMPUTED_VALUE"""),1.0) -> 1 | G17: =IFERROR(__xludf.DUMMYFUNCTION("""COMPUTED_VALUE"""),5.0) -> 5 | H17: =IFERROR(__xludf.DUMMYFUNCTION("""COMPUTED_VALUE"""),"LT proj.") -> LT proj. | I17: =IFERROR(__xludf.DUMMYFUNCTION("""COMPUTED_VALUE"""),"Panel") -> Panel | J17: =IFERROR(__xludf.DUMMYFUNCTION("""COMPUTED_VALUE"""),"All amenities") -> All amenities | K17: =IFERROR(__xludf.DUMMYFUNCTION("""COMPUTED_VALUE"""),46000.0) -> 46000 | L17: =IFERROR(__xludf.DUMMYFUNCTION("""COMPUTED_VALUE"""),56.9736358) -> 56.973636 | M17: =IFERROR(__xludf.DUMMYFUNCTION("""COMPUTED_VALUE"""),24.2335309150293) -> 24.233531
A18: =IFERROR(__xludf.DUMMYFUNCTION("""COMPUTED_VALUE"""),"For sale") -> For sale | B18: =IFERROR(__xludf.DUMMYFUNCTION("""COMPUTED_VALUE"""),"centrs") -> centrs | C18: =IFERROR(__xludf.DUMMYFUNCTION("""COMPUTED_VALUE"""),"Krāsotāju 25") -> Krāsotāju 25 | D18: =IFERROR(__xludf.DUMMYFUNCTION("""COMPUTED_VALUE"""),2.0) -> 2 | E18: =IFERROR(__xludf.DUMMYFUNCTION("""COMPUTED_VALUE"""),36.0) -> 36 | F18: =IFERROR(__xludf.DUMMYFUNCTION("""COMPUTED_VALUE"""),5.0) -> 5 | G18: =IFERROR(__xludf.DUMMYFUNCTION("""COMPUTED_VALUE"""),5.0) -> 5 | H18: =IFERROR(__xludf.DUMMYFUNCTION("""COMPUTED_VALUE"""),"P. kara") -> P. kara | I18: =IFERROR(__xludf.DUMMYFUNCTION("""COMPUTED_VALUE"""),"Masonry") -> Masonry | J18: =IFERROR(__xludf.DUMMYFUNCTION("""COMPUTED_VALUE"""),"All amenities") -> All amenities | K18: =IFERROR(__xludf.DUMMYFUNCTION("""COMPUTED_VALUE"""),54900.0) -> 54900 | L18: =IFERROR(__xludf.DUMMYFUNCTION("""COMPUTED_VALUE"""),56.9562996) -> 56.9563 | M18: =IFERROR(__xludf.DUMMYFUNCTION("""COMPUTED_VALUE"""),24.1467585) -> 24.146759
A19: =IFERROR(__xludf.DUMMYFUNCTION("""COMPUTED_VALUE"""),"For rent") -> For rent | B19: =IFERROR(__xludf.DUMMYFUNCTION("""COMPUTED_VALUE"""),"Ziepniekkalns") -> Ziepniekkalns | C19: =IFERROR(__xludf.DUMMYFUNCTION("""COMPUTED_VALUE"""),"Ozolciema 54") -> Ozolciema 54 | D19: =IFERROR(__xludf.DUMMYFUNCTION("""COMPUTED_VALUE"""),1.0) -> 1 | E19: =IFERROR(__xludf.DUMMYFUNCTION("""COMPUTED_VALUE"""),44.0) -> 44 | F19: =IFERROR(__xludf.DUMMYFUNCTION("""COMPUTED_VALUE"""),4.0) -> 4 | G19: =IFERROR(__xludf.DUMMYFUNCTION("""COMPUTED_VALUE"""),9.0) -> 9 | H19: =IFERROR(__xludf.DUMMYFUNCTION("""COMPUTED_VALUE"""),"M. ģim.") -> M. ģim. | I19: =IFERROR(__xludf.DUMMYFUNCTION("""COMPUTED_VALUE"""),"Panel") -> Panel | J19: =IFERROR(__xludf.DUMMYFUNCTION("""COMPUTED_VALUE"""),"All amenities") -> All amenities | K19: =IFERROR(__xludf.DUMMYFUNCTION("""COMPUTED_VALUE"""),240.0) -> 240 | L19: =IFERROR(__xludf.DUMMYFUNCTION("""COMPUTED_VALUE"""),56.9014001) -> 56.9014 | M19: =IFERROR(__xludf.DUMMYFUNCTION("""COMPUTED_VALUE"""),24.0998855645099) -> 24.099886
A20: =IFERROR(__xludf.DUMMYFUNCTION("""COMPUTED_VALUE"""),"For sale") -> For sale | B20: =IFERROR(__xludf.DUMMYFUNCTION("""COMPUTED_VALUE"""),"Ķengarags") -> Ķengarags | C20: =IFERROR(__xludf.DUMMYFUNCTION("""COMPUTED_VALUE"""),"Maskavas 268/5") -> Maskavas 268/5 | D20: =IFERROR(__xludf.DUMMYFUNCTION("""COMPUTED_VALUE"""),3.0) -> 3 | E20: =IFERROR(__xludf.DUMMYFUNCTION("""COMPUTED_VALUE"""),60.0) -> 60 | F20: =IFERROR(__xludf.DUMMYFUNCTION("""COMPUTED_VALUE"""),3.0) -> 3 | G20: =IFERROR(__xludf.DUMMYFUNCTION("""COMPUTED_VALUE"""),5.0) -> 5 | H20: =IFERROR(__xludf.DUMMYFUNCTION("""COMPUTED_VALUE"""),"Hrušč.") -> Hrušč. | I20: =IFERROR(__xludf.DUMMYFUNCTION("""COMPUTED_VALUE"""),"Panel") -> Panel | J20: =IFERROR(__xludf.DUMMYFUNCTION("""COMPUTED_VALUE"""),"All amenities") -> All amenities | K20: =IFERROR(__xludf.DUMMYFUNCTION("""COMPUTED_VALUE"""),56500.0) -> 56500 | L20: =IFERROR(__xludf.DUMMYFUNCTION("""COMPUTED_VALUE"""),56.8945857) -> 56.894586 | M20: =IFERROR(__xludf.DUMMYFUNCTION("""COMPUTED_VALUE"""),24.2163422) -> 24.216342
A21: =IFERROR(__xludf.DUMMYFUNCTION("""COMPUTED_VALUE"""),"For sale") -> For sale | B21: =IFERROR(__xludf.DUMMYFUNCTION("""COMPUTED_VALUE"""),"Mežciems") -> Mežciems | C21: =IFERROR(__xludf.DUMMYFUNCTION("""COMPUTED_VALUE"""),"Eizenšteina 57") -> Eizenšteina 57 | D21: =IFERROR(__xludf.DUMMYFUNCTION("""COMPUTED_VALUE"""),3.0) -> 3 | E21: =IFERROR(__xludf.DUMMYFUNCTION("""COMPUTED_VALUE"""),62.0) -> 62 | F21: =IFERROR(__xludf.DUMMYFUNCTION("""COMPUTED_VALUE"""),6.0) -> 6 | G21: =IFERROR(__xludf.DUMMYFUNCTION("""COMPUTED_VALUE"""),9.0) -> 9 | H21: =IFERROR(__xludf.DUMMYFUNCTION("""COMPUTED_VALUE"""),602.0) -> 602 | I21: =IFERROR(__xludf.DUMMYFUNCTION("""COMPUTED_VALUE"""),"Panel") -> Panel | J21: =IFERROR(__xludf.DUMMYFUNCTION("""COMPUTED_VALUE"""),"All amenities") -> All amenities | K21: =IFERROR(__xludf.DUMMYFUNCTION("""COMPUTED_VALUE"""),52500.0) -> 52500 | L21: =IFERROR(__xludf.DUMMYFUNCTION("""COMPUTED_VALUE"""),56.96342305) -> 56.963423 | M21: =IFERROR(__xludf.DUMMYFUNCTION("""COMPUTED_VALUE"""),24.2351297251986) -> 24.23513
A22: =IFERROR(__xludf.DUMMYFUNCTION("""COMPUTED_VALUE"""),"For rent") -> For rent | B22: =IFERROR(__xludf.DUMMYFUNCTION("""COMPUTED_VALUE"""),"Bolderāja") -> Bolderāja | C22: =IFERROR(__xludf.DUMMYFUNCTION("""COMPUTED_VALUE"""),"Stagaru 4") -> Stagaru 4 | D22: =IFERROR(__xludf.DUMMYFUNCTION("""COMPUTED_VALUE"""),2.0) -> 2 | E22: =IFERROR(__xludf.DUMMYFUNCTION("""COMPUTED_VALUE"""),50.0) -> 50 | F22: =IFERROR(__xludf.DUMMYFUNCTION("""COMPUTED_VALUE"""),2.0) -> 2 | G22: =IFERROR(__xludf.DUMMYFUNCTION("""COMPUTED_VALUE"""),5.0) -> 5 | H22: =IFERROR(__xludf.DUMMYFUNCTION("""COMPUTED_VALUE"""),"Specpr.") -> Specpr. | I22: =IFERROR(__xludf.DUMMYFUNCTION("""COMPUTED_VALUE"""),"Panel") -> Panel | J22: =IFERROR(__xludf.DUMMYFUNCTION("""COMPUTED_VALUE"""),"All amenities") -> All amenities | K22: =IFERROR(__xludf.DUMMYFUNCTION("""COMPUTED_VALUE"""),260.0) -> 260 | L22: =IFERROR(__xludf.DUMMYFUNCTION("""COMPUTED_VALUE"""),57.02965155) -> 57.029652 | M22: =IFERROR(__xludf.DUMMYFUNCTION("""COMPUTED_VALUE"""),24.0359751945236) -> 24.035975
A23: =IFERROR(__xludf.DUMMYFUNCTION("""COMPUTED_VALUE"""),"For sale") -> For sale | B23: =IFERROR(__xludf.DUMMYFUNCTION("""COMPUTED_VALUE"""),"Purvciems") -> Purvciems | C23: =IFERROR(__xludf.DUMMYFUNCTION("""COMPUTED_VALUE"""),"Dzelzavas 13") -> Dzelzavas 13 | D23: =IFERROR(__xludf.DUMMYFUNCTION("""COMPUTED_VALUE"""),2.0) -> 2 | E23: =IFERROR(__xludf.DUMMYFUNCTION("""COMPUTED_VALUE"""),44.0) -> 44 | F23: =IFERROR(__xludf.DUMMYFUNCTION("""COMPUTED_VALUE"""),4.0) -> 4 | G23: =IFERROR(__xludf.DUMMYFUNCTION("""COMPUTED_VALUE"""),5.0) -> 5 | H23: =IFERROR(__xludf.DUMMYFUNCTION("""COMPUTED_VALUE"""),"Hrušč.") -> Hrušč. | I23: =IFERROR(__xludf.DUMMYFUNCTION("""COMPUTED_VALUE"""),"Brick") -> Brick | J23: =IFERROR(__xludf.DUMMYFUNCTION("""COMPUTED_VALUE"""),"Without amenities") -> Without amenities | K23: =IFERROR(__xludf.DUMMYFUNCTION("""COMPUTED_VALUE"""),39000.0) -> 39000 | L23: =IFERROR(__xludf.DUMMYFUNCTION("""COMPUTED_VALUE"""),56.9636785) -> 56.963679 | M23: =IFERROR(__xludf.DUMMYFUNCTION("""COMPUTED_VALUE"""),24.1706167383245) -> 24.170617
A24: =IFERROR(__xludf.DUMMYFUNCTION("""COMPUTED_VALUE"""),"For rent") -> For rent | B24: =IFERROR(__xludf.DUMMYFUNCTION("""COMPUTED_VALUE"""),"centrs") -> centrs | C24: =IFERROR(__xludf.DUMMYFUNCTION("""COMPUTED_VALUE"""),"Čaka 33") -> Čaka 33 | D24: =IFERROR(__xludf.DUMMYFUNCTION("""COMPUTED_VALUE"""),2.0) -> 2 | E24: =IFERROR(__xludf.DUMMYFUNCTION("""COMPUTED_VALUE"""),40.0) -> 40 | F24: =IFERROR(__xludf.DUMMYFUNCTION("""COMPUTED_VALUE"""),4.0) -> 4 | G24: =IFERROR(__xludf.DUMMYFUNCTION("""COMPUTED_VALUE"""),6.0) -> 6 | H24: =IFERROR(__xludf.DUMMYFUNCTION("""COMPUTED_VALUE"""),"P. kara") -> P. kara | I24: =IFERROR(__xludf.DUMMYFUNCTION("""COMPUTED_VALUE"""),"Masonry") -> Masonry | J24: =IFERROR(__xludf.DUMMYFUNCTION("""COMPUTED_VALUE"""),"All amenities") -> All amenities | K24: =IFERROR(__xludf.DUMMYFUNCTION("""COMPUTED_VALUE"""),395.0) -> 395 | L24: =IFERROR(__xludf.DUMMYFUNCTION("""COMPUTED_VALUE"""),56.9521436) -> 56.952144 | M24: =IFERROR(__xludf.DUMMYFUNCTION("""COMPUTED_VALUE"""),24.1276865) -> 24.127686
A25: =IFERROR(__xludf.DUMMYFUNCTION("""COMPUTED_VALUE"""),"For rent") -> For rent | B25: =IFERROR(__xludf.DUMMYFUNCTION("""COMPUTED_VALUE"""),"centrs") -> centrs | C25: =IFERROR(__xludf.DUMMYFUNCTION("""COMPUTED_VALUE"""),"Bruņinieku 115") -> Bruņinieku 115 | D25: =IFERROR(__xludf.DUMMYFUNCTION("""COMPUTED_VALUE"""),2.0) -> 2 | E25: =IFERROR(__xludf.DUMMYFUNCTION("""COMPUTED_VALUE"""),45.0) -> 45 | F25: =IFERROR(__xludf.DUMMYFUNCTION("""COMPUTED_VALUE"""),2.0) -> 2 | G25: =IFERROR(__xludf.DUMMYFUNCTION("""COMPUTED_VALUE"""),4.0) -> 4 | H25: =IFERROR(__xludf.DUMMYFUNCTION("""COMPUTED_VALUE"""),"Renov.") -> Renov. | I25: =IFERROR(__xludf.DUMMYFUNCTION("""COMPUTED_VALUE"""),"Masonry") -> Masonry | J25: =IFERROR(__xludf.DUMMYFUNCTION("""COMPUTED_VALUE"""),"All amenities") -> All amenities | K25: =IFERROR(__xludf.DUMMYFUNCTION("""COMPUTED_VALUE"""),350.0) -> 350 | L25: =IFERROR(__xludf.DUMMYFUNCTION("""COMPUTED_VALUE"""),56.949971) -> 56.949971 | M25: =IFERROR(__xludf.DUMMYFUNCTION("""COMPUTED_VALUE"""),24.1441423352317) -> 24.144142
A26: =IFERROR(__xludf.DUMMYFUNCTION("""COMPUTED_VALUE"""),"For rent") -> For rent | B26: =IFERROR(__xludf.DUMMYFUNCTION("""COMPUTED_VALUE"""),"Grīziņkalns") -> Grīziņkalns | C26: =IFERROR(__xludf.DUMMYFUNCTION("""COMPUTED_VALUE"""),"Alauksta 4a") -> Alauksta 4a | D26: =IFERROR(__xludf.DUMMYFUNCTION("""COMPUTED_VALUE"""),1.0) -> 1 | E26: =IFERROR(__xludf.DUMMYFUNCTION("""COMPUTED_VALUE"""),26.0) -> 26 | F26: =IFERROR(__xludf.DUMMYFUNCTION("""COMPUTED_VALUE"""),2.0) -> 2 | G26: =IFERROR(__xludf.DUMMYFUNCTION("""COMPUTED_VALUE"""),3.0) -> 3 | H26: =IFERROR(__xludf.DUMMYFUNCTION("""COMPUTED_VALUE"""),"Renov.") -> Renov. | I26: =IFERROR(__xludf.DUMMYFUNCTION("""COMPUTED_VALUE"""),"Wood") -> Wood | J26: =IFERROR(__xludf.DUMMYFUNCTION("""COMPUTED_VALUE"""),"All amenities") -> All amenities | K26: =IFERROR(__xludf.DUMMYFUNCTION("""COMPUTED_VALUE"""),345.0) -> 345 | L26: =IFERROR(__xludf.DUMMYFUNCTION("""COMPUTED_VALUE"""),56.9610304) -> 56.96103 | M26: =IFERROR(__xludf.DUMMYFUNCTION("""COMPUTED_VALUE"""),24.1476406) -> 24.147641
A27: =IFERROR(__xludf.DUMMYFUNCTION("""COMPUTED_VALUE"""),"For rent") -> For rent | B27: =IFERROR(__xludf.DUMMYFUNCTION("""COMPUTED_VALUE"""),"Ziepniekkalns") -> Ziepniekkalns | C27: =IFERROR(__xludf.DUMMYFUNCTION("""COMPUTED_VALUE"""),"Kartupeļu 47") -> Kartupeļu 47 | D27: =IFERROR(__xludf.DUMMYFUNCTION("""COMPUTED_VALUE"""),2.0) -> 2 | E27: =IFERROR(__xludf.DUMMYFUNCTION("""COMPUTED_VALUE"""),56.0) -> 56 | F27: =IFERROR(__xludf.DUMMYFUNCTION("""COMPUTED_VALUE"""),8.0) -> 8 | G27: =IFERROR(__xludf.DUMMYFUNCTION("""COMPUTED_VALUE"""),9.0) -> 9 | H27: =IFERROR(__xludf.DUMMYFUNCTION("""COMPUTED_VALUE"""),"Specpr.") -> Specpr. | I27: =IFERROR(__xludf.DUMMYFUNCTION("""COMPUTED_VALUE"""),"Brick") -> Brick | J27: =IFERROR(__xludf.DUMMYFUNCTION("""COMPUTED_VALUE"""),"All amenities") -> All amenities | K27: =IFERROR(__xludf.DUMMYFUNCTION("""COMPUTED_VALUE"""),250.0) -> 250 | L27: =IFERROR(__xludf.DUMMYFUNCTION("""COMPUTED_VALUE"""),56.91095995) -> 56.91096 | M27: =IFERROR(__xludf.DUMMYFUNCTION("""COMPUTED_VALUE"""),24.1100004569314) -> 24.11
A28: =IFERROR(__xludf.DUMMYFUNCTION("""COMPUTED_VALUE"""),"For rent") -> For rent | B28: =IFERROR(__xludf.DUMMYFUNCTION("""COMPUTED_VALUE"""),"Bolderāja") -> Bolderāja | C28: =IFERROR(__xludf.DUMMYFUNCTION("""COMPUTED_VALUE"""),"Gobas 16") -> Gobas 16 | D28: =IFERROR(__xludf.DUMMYFUNCTION("""COMPUTED_VALUE"""),1.0) -> 1 | E28: =IFERROR(__xludf.DUMMYFUNCTION("""COMPUTED_VALUE"""),34.0) -> 34 | F28: =IFERROR(__xludf.DUMMYFUNCTION("""COMPUTED_VALUE"""),3.0) -> 3 | G28: =IFERROR(__xludf.DUMMYFUNCTION("""COMPUTED_VALUE"""),5.0) -> 5 | H28: =IFERROR(__xludf.DUMMYFUNCTION("""COMPUTED_VALUE"""),103.0) -> 103 | I28: =IFERROR(__xludf.DUMMYFUNCTION("""COMPUTED_VALUE"""),"Brick-Panel") -> Brick-Panel | J28: =IFERROR(__xludf.DUMMYFUNCTION("""COMPUTED_VALUE"""),"All amenities") -> All amenities | K28: =IFERROR(__xludf.DUMMYFUNCTION("""COMPUTED_VALUE"""),210.0) -> 210 | L28: =IFERROR(__xludf.DUMMYFUNCTION("""COMPUTED_VALUE"""),57.03135185) -> 57.031352 | M28: =IFERROR(__xludf.DUMMYFUNCTION("""COMPUTED_VALUE"""),24.0508646842677) -> 24.050865
A29: =IFERROR(__xludf.DUMMYFUNCTION("""COMPUTED_VALUE"""),"For sale") -> For sale | B29: =IFERROR(__xludf.DUMMYFUNCTION("""COMPUTED_VALUE"""),"Dreiliņi") -> Dreiliņi | C29: =IFERROR(__xludf.DUMMYFUNCTION("""COMPUTED_VALUE"""),"Valtera 5") -> Valtera 5 | D29: =IFERROR(__xludf.DUMMYFUNCTION("""COMPUTED_VALUE"""),4.0) -> 4 | E29: =IFERROR(__xludf.DUMMYFUNCTION("""COMPUTED_VALUE"""),78.0) -> 78 | F29: =IFERROR(__xludf.DUMMYFUNCTION("""COMPUTED_VALUE"""),1.0) -> 1 | G29: =IFERROR(__xludf.DUMMYFUNCTION("""COMPUTED_VALUE"""),9.0) -> 9 | H29: =IFERROR(__xludf.DUMMYFUNCTION("""COMPUTED_VALUE"""),602.0) -> 602 | I29: =IFERROR(__xludf.DUMMYFUNCTION("""COMPUTED_VALUE"""),"Panel") -> Panel | J29: =IFERROR(__xludf.DUMMYFUNCTION("""COMPUTED_VALUE"""),"All amenities") -> All amenities | K29: =IFERROR(__xludf.DUMMYFUNCTION("""COMPUTED_VALUE"""),91000.0) -> 91000 | L29: =IFERROR(__xludf.DUMMYFUNCTION("""COMPUTED_VALUE"""),56.9469271499999) -> 56.946927 | M29: =IFERROR(__xludf.DUMMYFUNCTION("""COMPUTED_VALUE"""),24.2365113562527) -> 24.236511
A30: =IFERROR(__xludf.DUMMYFUNCTION("""COMPUTED_VALUE"""),"For sale") -> For sale | B30: =IFERROR(__xludf.DUMMYFUNCTION("""COMPUTED_VALUE"""),"Ķengarags") -> Ķengarags | C30: =IFERROR(__xludf.DUMMYFUNCTION("""COMPUTED_VALUE"""),"Prūšu 22") -> Prūšu 22 | D30: =IFERROR(__xludf.DUMMYFUNCTION("""COMPUTED_VALUE"""),2.0) -> 2 | E30: =IFERROR(__xludf.DUMMYFUNCTION("""COMPUTED_VALUE"""),42.0) -> 42 | F30: =IFERROR(__xludf.DUMMYFUNCTION("""COMPUTED_VALUE"""),3.0) -> 3 | G30: =IFERROR(__xludf.DUMMYFUNCTION("""COMPUTED_VALUE"""),5.0) -> 5 | H30: =IFERROR(__xludf.DUMMYFUNCTION("""COMPUTED_VALUE"""),"Hrušč.") -> Hrušč. | I30: =IFERROR(__xludf.DUMMYFUNCTION("""COMPUTED_VALUE"""),"Brick") -> Brick | J30: =IFERROR(__xludf.DUMMYFUNCTION("""COMPUTED_VALUE"""),"All amenities") -> All amenities | K30: =IFERROR(__xludf.DUMMYFUNCTION("""COMPUTED_VALUE"""),45900.0) -> 45900 | L30: =IFERROR(__xludf.DUMMYFUNCTION("""COMPUTED_VALUE"""),56.9134761) -> 56.913476 | M30: =IFERROR(__xludf.DUMMYFUNCTION("""COMPUTED_VALUE"""),24.18677075) -> 24.186771
A31: =IFERROR(__xludf.DUMMYFUNCTION("""COMPUTED_VALUE"""),"For sale") -> For sale | B31: =IFERROR(__xludf.DUMMYFUNCTION("""COMPUTED_VALUE"""),"Pļavnieki") -> Pļavnieki | C31: =IFERROR(__xludf.DUMMYFUNCTION("""COMPUTED_VALUE"""),"Dzeņu 12") -> Dzeņu 12 | D31: =IFERROR(__xludf.DUMMYFUNCTION("""COMPUTED_VALUE"""),1.0) -> 1 | E31: =IFERROR(__xludf.DUMMYFUNCTION("""COMPUTED_VALUE"""),35.0) -> 35 | F31: =IFERROR(__xludf.DUMMYFUNCTION("""COMPUTED_VALUE"""),1.0) -> 1 | G31: =IFERROR(__xludf.DUMMYFUNCTION("""COMPUTED_VALUE"""),9.0) -> 9 | H31: =IFERROR(__xludf.DUMMYFUNCTION("""COMPUTED_VALUE"""),602.0) -> 602 | I31: =IFERROR(__xludf.DUMMYFUNCTION("""COMPUTED_VALUE"""),"Brick-Panel") -> Brick-Panel | J31: =IFERROR(__xludf.DUMMYFUNCTION("""COMPUTED_VALUE"""),"All amenities") -> All amenities | K31: =IFERROR(__xludf.DUMMYFUNCTION("""COMPUTED_VALUE"""),37000.0) -> 37000 | L31: =IFERROR(__xludf.DUMMYFUNCTION("""COMPUTED_VALUE"""),56.9397226) -> 56.939723 | M31: =IFERROR(__xludf.DUMMYFUNCTION("""COMPUTED_VALUE"""),24.2126243664139) -> 24.212624
A32: =IFERROR(__xludf.DUMMYFUNCTION("""COMPUTED_VALUE"""),"For rent") -> For rent | B32: =IFERROR(__xludf.DUMMYFUNCTION("""COMPUTED_VALUE"""),"Dzegužkalns") -> Dzegužkalns | C32: =IFERROR(__xludf.DUMMYFUNCTION("""COMPUTED_VALUE"""),"Purva 25") -> Purva 25 | D32: =IFERROR(__xludf.DUMMYFUNCTION("""COMPUTED_VALUE"""),1.0) -> 1 | E32: =IFERROR(__xludf.DUMMYFUNCTION("""COMPUTED_VALUE"""),29.0) -> 29 | F32: =IFERROR(__xludf.DUMMYFUNCTION("""COMPUTED_VALUE"""),4.0) -> 4 | G32: =IFERROR(__xludf.DUMMYFUNCTION("""COMPUTED_VALUE"""),5.0) -> 5 | H32: =IFERROR(__xludf.DUMMYFUNCTION("""COMPUTED_VALUE"""),"LT proj.") -> LT proj. | I32: =IFERROR(__xludf.DUMMYFUNCTION("""COMPUTED_VALUE"""),"Panel") -> Panel | J32: =IFERROR(__xludf.DUMMYFUNCTION("""COMPUTED_VALUE"""),"All amenities") -> All amenities | K32: =IFERROR(__xludf.DUMMYFUNCTION("""COMPUTED_VALUE"""),240.0) -> 240 | L32: =IFERROR(__xludf.DUMMYFUNCTION("""COMPUTED_VALUE"""),56.95770335) -> 56.957703 | M32: =IFERROR(__xludf.DUMMYFUNCTION("""COMPUTED_VALUE"""),24.0505207014209) -> 24.050521
A33: =IFERROR(__xludf.DUMMYFUNCTION("""COMPUTED_VALUE"""),"For rent") -> For rent | B33: =IFERROR(__xludf.DUMMYFUNCTION("""COMPUTED_VALUE"""),"Imanta") -> Imanta | C33: =IFERROR(__xludf.DUMMYFUNCTION("""COMPUTED_VALUE"""),"Slokas 130a") -> Slokas 130a | D33: =IFERROR(__xludf.DUMMYFUNCTION("""COMPUTED_VALUE"""),2.0) -> 2 | E33: =IFERROR(__xludf.DUMMYFUNCTION("""COMPUTED_VALUE"""),60.0) -> 60 | F33: =IFERROR(__xludf.DUMMYFUNCTION("""COMPUTED_VALUE"""),3.0) -> 3 | G33: =IFERROR(__xludf.DUMMYFUNCTION("""COMPUTED_VALUE"""),8.0) -> 8 | H33: =IFERROR(__xludf.DUMMYFUNCTION("""COMPUTED_VALUE"""),"Jaun.") -> Jaun. | I33: =IFERROR(__xludf.DUMMYFUNCTION("""COMPUTED_VALUE"""),"Masonry") -> Masonry | J33: =IFERROR(__xludf.DUMMYFUNCTION("""COMPUTED_VALUE"""),"All amenities") -> All amenities | K33: =IFERROR(__xludf.DUMMYFUNCTION("""COMPUTED_VALUE"""),580.0) -> 580 | L33: =IFERROR(__xludf.DUMMYFUNCTION("""COMPUTED_VALUE"""),56.96485355) -> 56.964854 | M33: =IFERROR(__xludf.DUMMYFUNCTION("""COMPUTED_VALUE"""),24.01574948511) -> 24.015749
A34: =IFERROR(__xludf.DUMMYFUNCTION("""COMPUTED_VALUE"""),"For sale") -> For sale | B34: =IFERROR(__xludf.DUMMYFUNCTION("""COMPUTED_VALUE"""),"Imanta") -> Imanta | C34: =IFERROR(__xludf.DUMMYFUNCTION("""COMPUTED_VALUE"""),"Slokas 130a") -> Slokas 130a | D34: =IFERROR(__xludf.DUMMYFUNCTION("""COMPUTED_VALUE"""),2.0) -> 2 | E34: =IFERROR(__xludf.DUMMYFUNCTION("""COMPUTED_VALUE"""),62.0) -> 62 | F34: =IFERROR(__xludf.DUMMYFUNCTION("""COMPUTED_VALUE"""),3.0) -> 3 | G34: =IFERROR(__xludf.DUMMYFUNCTION("""COMPUTED_VALUE"""),5.0) -> 5 | H34: =IFERROR(__xludf.DUMMYFUNCTION("""COMPUTED_VALUE"""),"Jaun.") -> Jaun. | I34: =IFERROR(__xludf.DUMMYFUNCTION("""COMPUTED_VALUE"""),"Masonry") -> Masonry | J34: =IFERROR(__xludf.DUMMYFUNCTION("""COMPUTED_VALUE"""),"All amenities") -> All amenities | K34: =IFERROR(__xludf.DUMMYFUNCTION("""COMPUTED_VALUE"""),120000.0) -> 120000 | L34: =IFERROR(__xludf.DUMMYFUNCTION("""COMPUTED_VALUE"""),56.96485355) -> 56.964854 | M34: =IFERROR(__xludf.DUMMYFUNCTION("""COMPUTED_VALUE"""),24.01574948511) -> 24.015749
A35: =IFERROR(__xludf.DUMMYFUNCTION("""COMPUTED_VALUE"""),"For rent") -> For rent | B35: =IFERROR(__xludf.DUMMYFUNCTION("""COMPUTED_VALUE"""),"centrs") -> centrs | C35: =IFERROR(__xludf.DUMMYFUNCTION("""COMPUTED_VALUE"""),"Indrānu 13") -> Indrānu 13 | D35: =IFERROR(__xludf.DUMMYFUNCTION("""COMPUTED_VALUE"""),1.0) -> 1 | E35: =IFERROR(__xludf.DUMMYFUNCTION("""COMPUTED_VALUE"""),34.0) -> 34 | F35: =IFERROR(__xludf.DUMMYFUNCTION("""COMPUTED_VALUE"""),5.0) -> 5 | G35: =IFERROR(__xludf.DUMMYFUNCTION("""COMPUTED_VALUE"""),5.0) -> 5 | H35: =IFERROR(__xludf.DUMMYFUNCTION("""COMPUTED_VALUE"""),"LT proj.") -> LT proj. | I35: =IFERROR(__xludf.DUMMYFUNCTION("""COMPUTED_VALUE"""),"Brick-Panel") -> Brick-Panel | J35: =IFERROR(__xludf.DUMMYFUNCTION("""COMPUTED_VALUE"""),"All amenities") -> All amenities | K35: =IFERROR(__xludf.DUMMYFUNCTION("""COMPUTED_VALUE"""),320.0) -> 320 | L35: =IFERROR(__xludf.DUMMYFUNCTION("""COMPUTED_VALUE"""),56.9685959) -> 56.968596 | M35: =IFERROR(__xludf.DUMMYFUNCTION("""COMPUTED_VALUE"""),24.1452571692525) -> 24.145257
A36: =IFERROR(__xludf.DUMMYFUNCTION("""COMPUTED_VALUE"""),"For sale") -> For sale | B36: =IFERROR(__xludf.DUMMYFUNCTION("""COMPUTED_VALUE"""),"Ķengarags") -> Ķengarags | C36: =IFERROR(__xludf.DUMMYFUNCTION("""COMPUTED_VALUE"""),"Festivāla 1") -> Festivāla 1 | D36: =IFERROR(__xludf.DUMMYFUNCTION("""COMPUTED_VALUE"""),3.0) -> 3 | E36: =IFERROR(__xludf.DUMMYFUNCTION("""COMPUTED_VALUE"""),55.0) -> 55 | F36: =IFERROR(__xludf.DUMMYFUNCTION("""COMPUTED_VALUE"""),3.0) -> 3 | G36: =IFERROR(__xludf.DUMMYFUNCTION("""COMPUTED_VALUE"""),5.0) -> 5 | H36: =IFERROR(__xludf.DUMMYFUNCTION("""COMPUTED_VALUE"""),"Specpr.") -> Specpr. | I36: =IFERROR(__xludf.DUMMYFUNCTION("""COMPUTED_VALUE"""),"Brick") -> Brick | J36: =IFERROR(__xludf.DUMMYFUNCTION("""COMPUTED_VALUE"""),"All amenities") -> All amenities | K36: =IFERROR(__xludf.DUMMYFUNCTION("""COMPUTED_VALUE"""),43000.0) -> 43000 | L36: =IFERROR(__xludf.DUMMYFUNCTION("""COMPUTED_VALUE"""),56.90348845) -> 56.903488 | M36: =IFERROR(__xludf.DUMMYFUNCTION("""COMPUTED_VALUE"""),24.20369795) -> 24.203698
A37: =IFERROR(__xludf.DUMMYFUNCTION("""COMPUTED_VALUE"""),"For rent") -> For rent | B37: =IFERROR(__xludf.DUMMYFUNCTION("""COMPUTED_VALUE"""),"Purvciems") -> Purvciems | C37: =IFERROR(__xludf.DUMMYFUNCTION("""COMPUTED_VALUE"""),"Ieriķu 58") -> Ieriķu 58 | D37: =IFERROR(__xludf.DUMMYFUNCTION("""COMPUTED_VALUE"""),1.0) -> 1 | E37: =IFERROR(__xludf.DUMMYFUNCTION("""COMPUTED_VALUE"""),43.0) -> 43 | F37: =IFERROR(__xludf.DUMMYFUNCTION("""COMPUTED_VALUE"""),9.0) -> 9 | G37: =IFERROR(__xludf.DUMMYFUNCTION("""COMPUTED_VALUE"""),9.0) -> 9 | H37: =IFERROR(__xludf.DUMMYFUNCTION("""COMPUTED_VALUE"""),"Specpr.") -> Specpr. | I37: =IFERROR(__xludf.DUMMYFUNCTION("""COMPUTED_VALUE"""),"Brick") -> Brick | J37: =IFERROR(__xludf.DUMMYFUNCTION("""COMPUTED_VALUE"""),"All amenities") -> All amenities | K37: =IFERROR(__xludf.DUMMYFUNCTION("""COMPUTED_VALUE"""),25.0) -> 25 | L37: =IFERROR(__xludf.DUMMYFUNCTION("""COMPUTED_VALUE"""),56.9655674) -> 56.965567 | M37: =IFERROR(__xludf.DUMMYFUNCTION("""COMPUTED_VALUE"""),24.1830043136253) -> 24.183004
A38: =IFERROR(__xludf.DUMMYFUNCTION("""COMPUTED_VALUE"""),"For rent") -> For rent | B38: =IFERROR(__xludf.DUMMYFUNCTION("""COMPUTED_VALUE"""),"Ķīpsala") -> Ķīpsala | C38: =IFERROR(__xludf.DUMMYFUNCTION("""COMPUTED_VALUE"""),"Balasta d. 72") -> Balasta d. 72 | D38: =IFERROR(__xludf.DUMMYFUNCTION("""COMPUTED_VALUE"""),2.0) -> 2 | E38: =IFERROR(__xludf.DUMMYFUNCTION("""COMPUTED_VALUE"""),86.0) -> 86 | F38: =IFERROR(__xludf.DUMMYFUNCTION("""COMPUTED_VALUE"""),2.0) -> 2 | G38: =IFERROR(__xludf.DUMMYFUNCTION("""COMPUTED_VALUE"""),4.0) -> 4 | H38: =IFERROR(__xludf.DUMMYFUNCTION("""COMPUTED_VALUE"""),"Jaun.") -> Jaun. | I38: =IFERROR(__xludf.DUMMYFUNCTION("""COMPUTED_VALUE"""),"Masonry") -> Masonry | J38: =IFERROR(__xludf.DUMMYFUNCTION("""COMPUTED_VALUE"""),"All amenities") -> All amenities | K38: =IFERROR(__xludf.DUMMYFUNCTION("""COMPUTED_VALUE"""),1200.0) -> 1200 | L38: =IFERROR(__xludf.DUMMYFUNCTION("""COMPUTED_VALUE"""),56.9489344) -> 56.948934 | M38: =IFERROR(__xludf.DUMMYFUNCTION("""COMPUTED_VALUE"""),24.0882804) -> 24.08828
A39: =IFERROR(__xludf.DUMMYFUNCTION("""COMPUTED_VALUE"""),"For rent") -> For rent | B39: =IFERROR(__xludf.DUMMYFUNCTION("""COMPUTED_VALUE"""),"centrs") -> centrs | C39: =IFERROR(__xludf.DUMMYFUNCTION("""COMPUTED_VALUE"""),"Barona 14") -> Barona 14 | D39: =IFERROR(__xludf.DUMMYFUNCTION("""COMPUTED_VALUE"""),1.0) -> 1 | E39: =IFERROR(__xludf.DUMMYFUNCTION("""COMPUTED_VALUE"""),40.0) -> 40 | F39: =IFERROR(__xludf.DUMMYFUNCTION("""COMPUTED_VALUE"""),4.0) -> 4 | G39: =IFERROR(__xludf.DUMMYFUNCTION("""COMPUTED_VALUE"""),5.0) -> 5 | H39: =IFERROR(__xludf.DUMMYFUNCTION("""COMPUTED_VALUE"""),"Renov.") -> Renov. | I39: =IFERROR(__xludf.DUMMYFUNCTION("""COMPUTED_VALUE"""),"Masonry") -> Masonry | J39: =IFERROR(__xludf.DUMMYFUNCTION("""COMPUTED_VALUE"""),"All amenities") -> All amenities | K39: =IFERROR(__xludf.DUMMYFUNCTION("""COMPUTED_VALUE"""),600.0) -> 600 | L39: =IFERROR(__xludf.DUMMYFUNCTION("""COMPUTED_VALUE"""),56.9506147) -> 56.950615 | M39: =IFERROR(__xludf.DUMMYFUNCTION("""COMPUTED_VALUE"""),24.1212313) -> 24.121231
A40: =IFERROR(__xludf.DUMMYFUNCTION("""COMPUTED_VALUE"""),"For rent") -> For rent | B40: =IFERROR(__xludf.DUMMYFUNCTION("""COMPUTED_VALUE"""),"centrs") -> centrs | C40: =IFERROR(__xludf.DUMMYFUNCTION("""COMPUTED_VALUE"""),"Bruņinieku 64") -> Bruņinieku 64 | D40: =IFERROR(__xludf.DUMMYFUNCTION("""COMPUTED_VALUE"""),2.0) -> 2 | E40: =IFERROR(__xludf.DUMMYFUNCTION("""COMPUTED_VALUE"""),36.0) -> 36 | F40: =IFERROR(__xludf.DUMMYFUNCTION("""COMPUTED_VALUE"""),3.0) -> 3 | G40: =IFERROR(__xludf.DUMMYFUNCTION("""COMPUTED_VALUE"""),3.0) -> 3 | H40: =IFERROR(__xludf.DUMMYFUNCTION("""COMPUTED_VALUE"""),"P. kara") -> P. kara | I40: =IFERROR(__xludf.DUMMYFUNCTION("""COMPUTED_VALUE"""),"Brick") -> Brick | J40: =IFERROR(__xludf.DUMMYFUNCTION("""COMPUTED_VALUE"""),"All amenities") -> All amenities | K40: =IFERROR(__xludf.DUMMYFUNCTION("""COMPUTED_VALUE"""),250.0) -> 250 | L40: =IFERROR(__xludf.DUMMYFUNCTION("""COMPUTED_VALUE"""),56.9530706) -> 56.953071 | M40: =IFERROR(__xludf.DUMMYFUNCTION("""COMPUTED_VALUE"""),24.1376419) -> 24.137642
...

Sheet Pivot_district

Sheet Pivot_rooms

Sheet Pivot_rent

Sheet Dashboard
A1: Riga Real Estate Market Analysis
I43: KPI Summary
I44: Total listings: | J44: =Analysis!B2 -> 4689
I45: For sale: | J45: =Analysis!B3 -> 2680
I46: For rent: | J46: =Analysis!B4 -> 1525
I47: Avg sale price: | J47: =ROUND(Analysis!B5,0)&" €" -> 92104 €
I48: Avg rent price: | J48: =ROUND(Analysis!B6,0)&" €" -> 425 €
I49: 2-room centrs (sale): | J49: =ROUND(Analysis!B14,0)&" €" -> 91035 €
